Workbook

Sheet Flips
A1: # | B1: Player | C1: Player ID | D1: Nationality | E1: Age when bought | F1: Age estimated? | G1: Potential | H1: Position | I1: Height (cm) | J1: Draft pick (of 48) | K1: Bought from drafting team? | L1: Bought on | M1: Buy price ($) | N1: Sold on | O1: Sale price ($) | P1: Profit ($) | Q1: Sale ÷ buy | R1: Days held | S1: Salary in season bought ($/wk) | T1: Salary in season sold ($/wk) | U1: Buy ÷ salary | V1: Sale ÷ salary | W1: Salary at 22 ($/wk) | X1: Salary at 24 ($/wk) | Y1: Salary at 26 ($/wk) | Z1: Highest salary ($/wk) | AA1: Last season with salary
A2: 1 | B2: Ignacio Saracina | C2: 41691320 | D2: España | E2: 18 | F2: Yes (from draft season) | G2: superstar | H2: PG | I2: 188 | J2: 41 | K2: No | L2: 42811 | M2: 15000 | N2: 42871 | O2: 98000 | P2: =O2-M2 | Q2: =IF(M2=0,"",O2/M2) | R2: =N2-L2 | S2: 3632 | T2: 3632 | U2: =M2/S2 | V2: =O2/S2 | Z2: 3934 | AA2: 40
A3: 2 | B3: Rauls Bersons | C3: 42106233 | D3: Latvija | E3: 18 | F3: Yes (from draft season) | G3: superstar | H3: PG | I3: 190 | J3: 26 | K3: No | L3: 42811 | M3: 1000 | N3: 42860 | O3: 121000 | P3: =O3-M3 | Q3: =IF(M3=0,"",O3/M3) | R3: =N3-L3 | S3: 3705 | T3: 3705 | U3: =M3/S3 | V3: =O3/S3 | Z3: 3705 | AA3: 38
A4: 3 | B4: Przemysław Kosterski | C4: 41385714 | D4: Polska | E4: 19 | F4: Yes (from draft season) | G4: MVP | H4: PF | I4: 196 | J4: 4 | K4: No | L4: 42811 | M4: 4000 | N4: 42856 | O4: 175000 | P4: =O4-M4 | Q4: =IF(M4=0,"",O4/M4) | R4: =N4-L4 | S4: 3314 | T4: 3314 | U4: =M4/S4 | V4: =O4/S4 | W4: 5644 | X4: 7023 | Y4: 8604 | Z4: 8630 | AA4: 46
A5: 4 | B5: Nikanor Liamaeu | C5: 42281787 | D5: Belarus | E5: 18 | F5: Yes (from draft season) | G5: superstar | H5: PG | I5: 196 | J5: 26 | K5: Yes | L5: 42811 | M5: 10000 | N5: 42847 | O5: 190800 | P5: =O5-M5 | Q5: =IF(M5=0,"",O5/M5) | R5: =N5-L5 | S5: 4136 | T5: 4136 | U5: =M5/S5 | V5: =O5/S5 | W5: 9798 | X5: 10207 | Z5: 10312 | AA5: 45
A6: 5 | B6: Yiannis Mpaxevanakis | C6: 41862455 | D6: Hellas | E6: 18 | F6: Yes (from draft season) | G6: MVP | H6: PG | I6: 203 | J6: 14 | K6: Yes | L6: 42811 | M6: 34400 | N6: 42843 | O6: 372000 | P6: =O6-M6 | Q6: =IF(M6=0,"",O6/M6) | R6: =N6-L6 | S6: 2088 | T6: 2088 | U6: =M6/S6 | V6: =O6/S6 | W6: 6393 | X6: 6912 | Y6: 7090 | Z6: 7090 | AA6: 46
A7: 6 | B7: Wenceslao Ortega | C7: 41704433 | D7: España | E7: 18 | F7: Yes (from draft season) | G7: hall of famer | H7: PG | I7: 190 | J7: 48 | K7: No | L7: 42812 | M7: 4000 | N7: 42848 | O7: 272000 | P7: =O7-M7 | Q7: =IF(M7=0,"",O7/M7) | R7: =N7-L7 | S7: 2283 | T7: 2283 | U7: =M7/S7 | V7: =O7/S7 | W7: 2463 | X7: 2513 | Y7: 2501 | Z7: 2513 | AA7: 66
A8: 7 | B8: Austin Chamberlain | C8: 42352280 | D8: USA | E8: 18 | F8: Yes (from draft season) | G8: MVP | H8: C | I8: 193 | J8: 38 | K8: No | L8: 42908 | M8: 10000 | N8: 42938 | O8: 277500 | P8: =O8-M8 | Q8: =IF(M8=0,"",O8/M8) | R8: =N8-L8 | S8: 3218 | T8: 3218 | U8: =M8/S8 | V8: =O8/S8 | Z8: 3218 | AA8: 40
A9: 8 | B9: Matthieu Meyer | C9: 42604416 | D9: France | E9: 18 | F9: Yes (from draft season) | G9: MVP | H9: PG | I9: 201 | J9: 42 | K9: Yes | L9: 42908 | M9: 10000 | N9: 42938 | O9: 198000 | P9: =O9-M9 | Q9: =IF(M9=0,"",O9/M9) | R9: =N9-L9 | S9: 3131 | T9: 3131 | U9: =M9/S9 | V9: =O9/S9 | Z9: 3131 | AA9: 39
A10: 9 | B10: Thomas Berra | C10: 42601397 | D10: France | E10: 18 | F10: Yes (from draft season) | G10: hall of famer | H10: PG | I10: 201 | J10: 47 | K10: Yes | L10: 42908 | M10: 14000 | N10: 42954 | O10: 198000 | P10: =O10-M10 | Q10: =IF(M10=0,"",O10/M10) | R10: =N10-L10 | S10: 2432 | T10: 2432 | U10: =M10/S10 | V10: =O10/S10 | Z10: 2432 | AA10: 41
A11: 10 | B11: Linas Treinius | C11: 42725108 | D11: Lietuva | E11: 18 | F11: Yes (from draft season) | G11: hall of famer | H11: PG | I11: 190 | J11: 5 | K11: Yes | L11: 42908 | M11: 2000 | N11: 42952 | O11: 187000 | P11: =O11-M11 | Q11: =IF(M11=0,"",O11/M11) | R11: =N11-L11 | S11: 3201 | T11: 3201 | U11: =M11/S11 | V11: =O11/S11 | W11: 3557 | X11: 3557 | Y11: 3538 | Z11: 3557 | AA11: 53
A12: 11 | B12: Miroslav Vončina | C12: 43007337 | D12: Slovenija | E12: 18 | F12: Yes (from draft season) | G12: MVP | H12: PF | I12: 203 | J12: 16 | K12: No | L12: 42908 | M12: 1000 | N12: 42935 | O12: 175000 | P12: =O12-M12 | Q12: =IF(M12=0,"",O12/M12) | R12: =N12-L12 | S12: 3627 | T12: 3627 | U12: =M12/S12 | V12: =O12/S12 | W12: 7084 | X12: 8141 | Y12: 9212 | Z12: 10145 | AA12: 54
A13: 12 | B13: Manuel Prada | C13: 42443844 | D13: España | E13: 18 | F13: Yes (from draft season) | G13: hall of famer | H13: PG | I13: 201 | J13: 3 | K13: Yes | L13: 42908 | M13: 52100 | N13: 42936 | O13: 375000 | P13: =O13-M13 | Q13: =IF(M13=0,"",O13/M13) | R13: =N13-L13 | S13: 2924 | T13: 2924 | U13: =M13/S13 | V13: =O13/S13 | Z13: 3117 | AA13: 42
A14: 13 | B14: Sarolf Reinhardtshain | C14: 42943544 | D14: Polska | E14: 18 | F14: Yes (from draft season) | G14: MVP | H14: SF | I14: 185 | J14: 5 | K14: Yes | L14: 42910 | M14: 8000 | N14: 42962 | O14: 173400 | P14: =O14-M14 | Q14: =IF(M14=0,"",O14/M14) | R14: =N14-L14 | S14: 3446 | T14: 3446 | U14: =M14/S14 | V14: =O14/S14 | W14: 3232 | X14: 3232 | Y14: 3215 | Z14: 3446 | AA14: 66
A15: 14 | B15: Jurgis Fedorecas | C15: 43517742 | D15: Lietuva | E15: 18 | F15: Yes (from draft season) | G15: hall of famer | H15: SG | I15: 188 | J15: 16 | K15: Yes | L15: 43007 | M15: 50000 | N15: 43031 | O15: 400000 | P15: =O15-M15 | Q15: =IF(M15=0,"",O15/M15) | R15: =N15-L15 | S15: 3156 | T15: 3156 | U15: =M15/S15 | V15: =O15/S15 | Z15: 3156 | AA15: 40
A16: 15 | B16: Kevin Price | C16: 43143179 | D16: USA | E16: 18 | F16: Yes (from draft season) | G16: MVP | H16: SF | I16: 203 | J16: 43 | K16: No | L16: 43007 | M16: 3000 | N16: 43032 | O16: 272000 | P16: =O16-M16 | Q16: =IF(M16=0,"",O16/M16) | R16: =N16-L16 | S16: 2931 | T16: 2931 | U16: =M16/S16 | V16: =O16/S16 | Z16: 2931 | AA16: 42
A17: 16 | B17: Brett Barnes | C17: 43866699 | D17: Utopia | E17: 18 | F17: Yes (from draft season) | G17: superstar | H17: SF | I17: 188 | J17: 9 | K17: No | L17: 43007 | M17: 17000 | N17: 43054 | O17: 165000 | P17: =O17-M17 | Q17: =IF(M17=0,"",O17/M17) | R17: =N17-L17 | S17: 2819 | T17: 2819 | U17: =M17/S17 | V17: =O17/S17 | W17: 5717 | X17: 7690 | Z17: 7690 | AA17: 46
A18: 17 | B18: Kosmas Valsamakis | C18: 43437279 | D18: Hellas | E18: 18 | F18: Yes (from draft season) | G18: hall of famer | H18: PF | I18: 193 | J18: 14 | K18: Yes | L18: 43007 | M18: 2000 | N18: 43028 | O18: 198000 | P18: =O18-M18 | Q18: =IF(M18=0,"",O18/M18) | R18: =N18-L18 | S18: 3439 | T18: 3439 | U18: =M18/S18 | V18: =O18/S18 | W18: 9598 | X18: 11843 | Y18: 12792 | Z18: 14306 | AA18: 59
A19: 18 | B19: Ivan Morales | C19: 43840973 | D19: Uruguay | E19: 18 | F19: Yes (from draft season) | G19: hall of famer | H19: C | I19: 203 | J19: 14 | K19: No | L19: 43009 | M19: 50000 | N19: 43029 | O19: 390300 | P19: =O19-M19 | Q19: =IF(M19=0,"",O19/M19) | R19: =N19-L19 | S19: 3364 | T19: 3364 | U19: =M19/S19 | V19: =O19/S19 | W19: 7515 | X19: 9357 | Y19: 11406 | Z19: 13940 | AA19: 51
A20: 19 | B20: Crispino Cruz Neto | C20: 43200221 | D20: Brasil | E20: 18 | F20: Yes (from draft season) | G20: MVP | H20: C | I20: 188 | J20: 27 | K20: No | L20: 43010 | M20: 5000 | N20: 43073 | O20: 137800 | P20: =O20-M20 | Q20: =IF(M20=0,"",O20/M20) | R20: =N20-L20 | S20: 2783 | T20: 2783 | U20: =M20/S20 | V20: =O20/S20 | Z20: 2783 | AA20: 41
A21: 20 | B21: Kostakis Vrontakis | C21: 43437820 | D21: Hellas | E21: 18 | F21: Yes (from draft season) | G21: hall of famer | H21: SF | I21: 190 | J21: 30 | K21: Yes | L21: 43010 | M21: 12000 | N21: 43080 | O21: 165000 | P21: =O21-M21 | Q21: =IF(M21=0,"",O21/M21) | R21: =N21-L21 | S21: 2817 | T21: 2817 | U21: =M21/S21 | V21: =O21/S21 | W21: 3137 | X21: 3260 | Z21: 3260 | AA21: 46
A22: 21 | B22: Henryk Szwajka | C22: 43733059 | D22: Polska | E22: 18 | F22: Yes (from draft season) | G22: hall of famer | H22: PG | I22: 190 | J22: 22 | K22: Yes | L22: 43010 | M22: 33333 | N22: 43066 | O22: 195000 | P22: =O22-M22 | Q22: =IF(M22=0,"",O22/M22) | R22: =N22-L22 | S22: 2989 | T22: 2989 | U22: =M22/S22 | V22: =O22/S22 | W22: 4822 | X22: 5888 | Y22: 5894 | Z22: 6141 | AA22: 54
A23: 22 | B23: Miquel Canal | C23: 44059881 | D23: España | E23: 18 | F23: Yes (from draft season) | G23: MVP | H23: SF | I23: 193 | J23: 31 | K23: No | L23: 43104 | M23: 11000 | N23: 43149 | O23: 175000 | P23: =O23-M23 | Q23: =IF(M23=0,"",O23/M23) | R23: =N23-L23 | S23: 3551 | T23: 3551 | U23: =M23/S23 | V23: =O23/S23 | W23: 5295 | X23: 5576 | Y23: 5993 | Z23: 6417 | AA23: 58
A24: 23 | B24: Paolo Alvisi | C24: 44147373 | D24: Italia | E24: 18 | F24: Yes (from draft season) | G24: hall of famer | H24: SF | I24: 203 | J24: 19 | K24: Yes | L24: 43105 | M24: 22222 | N24: 43147 | O24: 187000 | P24: =O24-M24 | Q24: =IF(M24=0,"",O24/M24) | R24: =N24-L24 | S24: 2931 | T24: 2931 | U24: =M24/S24 | V24: =O24/S24 | Z24: 4444 | AA24: 44
A25: 24 | B25: Yiorgos Kokkinias | C25: 44229075 | D25: Hellas | E25: 18 | F25: Yes (from draft season) | G25: MVP | H25: PG | I25: 193 | J25: 25 | K25: Yes | L25: 43105 | M25: 2000 | N25: 43167 | O25: 232000 | P25: =O25-M25 | Q25: =IF(M25=0,"",O25/M25) | R25: =N25-L25 | S25: 3459 | T25: 3459 | U25: =M25/S25 | V25: =O25/S25 | W25: 9837 | X25: 32503 | Y25: 33473 | Z25: 35310 | AA25: 54
A26: 25 | B26: Pascual Vera | C26: 44633410 | D26: Uruguay | E26: 18 | F26: Yes (from draft season) | G26: hall of famer | H26: PF | I26: 201 | J26: 32 | K26: No | L26: 43105 | M26: 33333 | N26: 43145 | O26: 257100 | P26: =O26-M26 | Q26: =IF(M26=0,"",O26/M26) | R26: =N26-L26 | S26: 3461 | T26: 3461 | U26: =M26/S26 | V26: =O26/S26 | W26: 5071 | X26: 6337 | Y26: 6677 | Z26: 6951 | AA26: 56
A27: 26 | B27: Kostakis Aidonis | C27: 44226559 | D27: Hellas | E27: 18 | F27: Yes (from draft season) | G27: hall of famer | H27: SF | I27: 201 | J27: 4 | K27: Yes | L27: 43107 | M27: 51000 | N27: 43149 | O27: 272000 | P27: =O27-M27 | Q27: =IF(M27=0,"",O27/M27) | R27: =N27-L27 | S27: 3818 | T27: 3818 | U27: =M27/S27 | V27: =O27/S27 | W27: 4132 | X27: 4173 | Y27: 4206 | Z27: 4219 | AA27: 52
A28: 27 | B28: Giulio Bonvini | C28: 44150432 | D28: Italia | E28: 18 | F28: Yes (from draft season) | G28: hall of famer | H28: SF | I28: 206 | J28: 4 | K28: Yes | L28: 43108 | M28: 6000 | N28: 43136 | O28: 198000 | P28: =O28-M28 | Q28: =IF(M28=0,"",O28/M28) | R28: =N28-L28 | S28: 3230 | T28: 3230 | U28: =M28/S28 | V28: =O28/S28 | W28: 3513 | Z28: 3559 | AA28: 46
A29: 28 | B29: Sigas Kaupinis | C29: 44309144 | D29: Lietuva | E29: 18 | F29: Yes (from draft season) | G29: hall of famer | H29: PF | I29: 196 | J29: 26 | K29: Yes | L29: 43109 | M29: 40000 | N29: 43145 | O29: 295000 | P29: =O29-M29 | Q29: =IF(M29=0,"",O29/M29) | R29: =N29-L29 | S29: 2975 | T29: 2975 | U29: =M29/S29 | V29: =O29/S29 | W29: 16014 | X29: 21163 | Y29: 21652 | Z29: 22159 | AA29: 56
A30: 29 | B30: Nicanor Peñafuerte | C30: 44058673 | D30: España | E30: 18 | F30: Yes (from draft season) | G30: hall of famer | H30: C | I30: 203 | J30: 6 | K30: No | L30: 43111 | M30: 1000 | N30: 43151 | O30: 187000 | P30: =O30-M30 | Q30: =IF(M30=0,"",O30/M30) | R30: =N30-L30 | S30: 2668 | T30: 2668 | U30: =M30/S30 | V30: =O30/S30 | W30: 7838 | Y30: 9463 | Z30: 13286 | AA30: 53
A31: 30 | B31: Werner Diersfart | C31: 44100991 | D31: Deutschland | E31: 18 | F31: Yes (from draft season) | G31: hall of famer | H31: PF | I31: 196 | J31: 32 | K31: No | L31: 43114 | M31: 8000 | N31: 43150 | O31: 198000 | P31: =O31-M31 | Q31: =IF(M31=0,"",O31/M31) | R31: =N31-L31 | S31: 3190 | T31: 3190 | U31: =M31/S31 | V31: =O31/S31 | Z31: 3598 | AA31: 42
A32: 31 | B32: Dorjan Andreu | C32: 44946064 | D32: Italia | E32: 18 | F32: Yes (from draft season) | G32: hall of famer | H32: SF | I32: 188 | J32: 11 | K32: No | L32: 43203 | M32: 13000 | N32: 43231 | O32: 206100 | P32: =O32-M32 | Q32: =IF(M32=0,"",O32/M32) | R32: =N32-L32 | S32: 3938 | T32: 3938 | U32: =M32/S32 | V32: =O32/S32 | W32: 7830 | X32: 13585 | Y32: 13608 | Z32: 13620 | AA32: 54
A33: 32 | B33: Luca Sina | C33: 44946495 | D33: Italia | E33: 18 | F33: Yes (from draft season) | G33: MVP | H33: SF | I33: 198 | J33: 28 | K33: Yes | L33: 43204 | M33: 7000 | N33: 43245 | O33: 198000 | P33: =O33-M33 | Q33: =IF(M33=0,"",O33/M33) | R33: =N33-L33 | S33: 3021 | T33: 3021 | U33: =M33/S33 | V33: =O33/S33 | Z33: 4388 | AA33: 45
A34: 33 | B34: Artur Salawa | C34: 45324882 | D34: Polska | E34: 18 | F34: Yes (from draft season) | G34: hall of famer | H34: SF | I34: 198 | J34: 11 | K34: No | L34: 43204 | M34: 10000 | N34: 43235 | O34: 187000 | P34: =O34-M34 | Q34: =IF(M34=0,"",O34/M34) | R34: =N34-L34 | S34: 2752 | T34: 2752 | U34: =M34/S34 | V34: =O34/S34 | W34: 7220 | X34: 7227 | Y34: 8163 | Z34: 8349 | AA34: 52
A35: 34 | B35: Andrew Matthew Supranes | C35: 45306844 | D35: Pilipinas | E35: 18 | F35: Yes (from draft season) | G35: hall of famer | H35: SF | I35: 185 | J35: 32 | K35: No | L35: 43205 | M35: 12000 | N35: 43235 | O35: 301000 | P35: =O35-M35 | Q35: =IF(M35=0,"",O35/M35) | R35: =N35-L35 | S35: 3381 | T35: 3381 | U35: =M35/S35 | V35: =O35/S35 | W35: 12531 | X35: 22284 | Y35: 31365 | Z35: 37842 | AA35: 61
A36: 35 | B36: Adri de Henau | C36: 45078706 | D36: Nederland | E36: 18 | F36: Yes (from draft season) | G36: hall of famer | H36: SF | I36: 201 | J36: 15 | K36: No | L36: 43207 | M36: 6000 | N36: 43236 | O36: 198000 | P36: =O36-M36 | Q36: =IF(M36=0,"",O36/M36) | R36: =N36-L36 | S36: 3269 | T36: 3269 | U36: =M36/S36 | V36: =O36/S36 | W36: 7867 | X36: 8022 | Y36: 8102 | Z36: 9595 | AA36: 55
A37: 36 | B37: Simo Voltri | C37: 45232526 | D37: Eesti | E37: 18 | F37: Yes (from draft season) | G37: hall of famer | H37: SF | I37: 206 | J37: 32 | K37: Yes | L37: 43210 | M37: 32000 | N37: 43244 | O37: 252000 | P37: =O37-M37 | Q37: =IF(M37=0,"",O37/M37) | R37: =N37-L37 | S37: 3235 | T37: 3235 | U37: =M37/S37 | V37: =O37/S37 | W37: 4115 | X37: 4479 | Z37: 4583 | AA37: 49
A38: 37 | B38: Ralf Looft | C38: 44900658 | D38: Deutschland | E38: 18 | F38: Yes (from draft season) | G38: hall of famer | H38: PF | I38: 203 | J38: 48 | K38: No | L38: 43211 | M38: 29000 | N38: 43249 | O38: 198000 | P38: =O38-M38 | Q38: =IF(M38=0,"",O38/M38) | R38: =N38-L38 | S38: 3252 | T38: 3252 | U38: =M38/S38 | V38: =O38/S38 | W38: 8037 | X38: 10888 | Y38: 11066 | Z38: 11380 | AA38: 58
A39: 38 | B39: Bill Höstlius | C39: 45719792 | D39: Sverige | E39: 18 | F39: Yes (from draft season) | G39: hall of famer | H39: PF | I39: 203 | J39: 23 | K39: No | L39: 43301 | M39: 22222 | N39: 43340 | O39: 175000 | P39: =O39-M39 | Q39: =IF(M39=0,"",O39/M39) | R39: =N39-L39 | S39: 2979 | T39: 2979 | U39: =M39/S39 | V39: =O39/S39 | W39: 13486 | X39: 18221 | Y39: 18335 | Z39: 25764 | AA39: 64
A40: 39 | B40: Edvinas Slapcinskas | C40: 45887858 | D40: Lietuva | E40: 18 | F40: Yes (from draft season) | G40: MVP | H40: SF | I40: 185 | J40: 40 | K40: Yes | L40: 43301 | M40: 22222 | N40: 43331 | O40: 295000 | P40: =O40-M40 | Q40: =IF(M40=0,"",O40/M40) | R40: =N40-L40 | S40: 3807 | T40: 3807 | U40: =M40/S40 | V40: =O40/S40 | W40: 9811 | X40: 24391 | Y40: 38495 | Z40: 43138 | AA40: 63
...

Sheet Summary
A1: Młoty Stargard – teenage flips since 2017 | F1: Salary vs price
A3: Players flipped | B3: =COUNTA(Flips!B2:B135) | F3: Median salary in season bought ($/wk) | G3: =MEDIAN(Flips!$S$2:$S$135)
A4: Total spent ($) | B4: =SUM(Flips!M2:M135) | F4: Players whose salary changed during the hold | G4: =SUMPRODUCT(--(Flips!$S$2:$S$135<>Flips!$T$2:$T$135))
A5: Total received ($) | B5: =SUM(Flips!O2:O135) | F5: Median buy ÷ salary | G5: =MEDIAN(Flips!$U$2:$U$135)
A6: Total profit ($) | B6: =SUM(Flips!P2:P135) | F6: Median sale ÷ salary | G6: =MEDIAN(Flips!$V$2:$V$135)
A7: Median buy price ($) | B7: =MEDIAN(Flips!M2:M135) | F7: Median highest salary, bought 2020 or earlier ($/wk) | G7: {=MEDIAN(IF(YEAR(Flips!$L$2:$L$135)<=2020,Flips!$Z$2:$Z$135))}
A8: Median sale price ($) | B8: =MEDIAN(Flips!O2:O135) | F8: Players ever reaching $50k/wk | G8: =COUNTIF(Flips!$Z$2:$Z$135,">=50000")
A9: Median sale ÷ buy | B9: =MEDIAN(Flips!Q2:Q135) | F9: Players ever reaching $100k/wk | G9: =COUNTIF(Flips!$Z$2:$Z$135,">=100000")
A10: Median days held | B10: =MEDIAN(Flips!R2:R135)
A11: Bought from drafting team | B11: =COUNTIF(Flips!K2:K135,"Yes")
A13: By potential
A14: Value | B14: Players | C14: Median buy ($) | D14: Median sale ($)
A15: hall of famer | B15: =COUNTIF(Flips!$G$2:$G$135,A15) | C15: {=MEDIAN(IF(Flips!$G$2:$G$135=A15,Flips!$M$2:$M$135))} | D15: {=MEDIAN(IF(Flips!$G$2:$G$135=A15,Flips!$O$2:$O$135))}
A16: MVP | B16: =COUNTIF(Flips!$G$2:$G$135,A16) | C16: {=MEDIAN(IF(Flips!$G$2:$G$135=A16,Flips!$M$2:$M$135))} | D16: {=MEDIAN(IF(Flips!$G$2:$G$135=A16,Flips!$O$2:$O$135))}
A17: superstar | B17: =COUNTIF(Flips!$G$2:$G$135,A17) | C17: {=MEDIAN(IF(Flips!$G$2:$G$135=A17,Flips!$M$2:$M$135))} | D17: {=MEDIAN(IF(Flips!$G$2:$G$135=A17,Flips!$O$2:$O$135))}
A19: By position
A20: Value | B20: Players | C20: Median buy ($) | D20: Median sale ($)
A21: PG | B21: =COUNTIF(Flips!$H$2:$H$135,A21) | C21: {=MEDIAN(IF(Flips!$H$2:$H$135=A21,Flips!$M$2:$M$135))} | D21: {=MEDIAN(IF(Flips!$H$2:$H$135=A21,Flips!$O$2:$O$135))}
A22: SF | B22: =COUNTIF(Flips!$H$2:$H$135,A22) | C22: {=MEDIAN(IF(Flips!$H$2:$H$135=A22,Flips!$M$2:$M$135))} | D22: {=MEDIAN(IF(Flips!$H$2:$H$135=A22,Flips!$O$2:$O$135))}
A23: PF | B23: =COUNTIF(Flips!$H$2:$H$135,A23) | C23: {=MEDIAN(IF(Flips!$H$2:$H$135=A23,Flips!$M$2:$M$135))} | D23: {=MEDIAN(IF(Flips!$H$2:$H$135=A23,Flips!$O$2:$O$135))}
A24: C | B24: =COUNTIF(Flips!$H$2:$H$135,A24) | C24: {=MEDIAN(IF(Flips!$H$2:$H$135=A24,Flips!$M$2:$M$135))} | D24: {=MEDIAN(IF(Flips!$H$2:$H$135=A24,Flips!$O$2:$O$135))}
A25: SG | B25: =COUNTIF(Flips!$H$2:$H$135,A25) | C25: {=MEDIAN(IF(Flips!$H$2:$H$135=A25,Flips!$M$2:$M$135))} | D25: {=MEDIAN(IF(Flips!$H$2:$H$135=A25,Flips!$O$2:$O$135))}
A27: By nationality
A28: Value | B28: Players | C28: Median buy ($) | D28: Median sale ($)
A29: Utopia | B29: =COUNTIF(Flips!$D$2:$D$135,A29) | C29: {=MEDIAN(IF(Flips!$D$2:$D$135=A29,Flips!$M$2:$M$135))} | D29: {=MEDIAN(IF(Flips!$D$2:$D$135=A29,Flips!$O$2:$O$135))}
A30: España | B30: =COUNTIF(Flips!$D$2:$D$135,A30) | C30: {=MEDIAN(IF(Flips!$D$2:$D$135=A30,Flips!$M$2:$M$135))} | D30: {=MEDIAN(IF(Flips!$D$2:$D$135=A30,Flips!$O$2:$O$135))}
A31: Polska | B31: =COUNTIF(Flips!$D$2:$D$135,A31) | C31: {=MEDIAN(IF(Flips!$D$2:$D$135=A31,Flips!$M$2:$M$135))} | D31: {=MEDIAN(IF(Flips!$D$2:$D$135=A31,Flips!$O$2:$O$135))}
A32: Lietuva | B32: =COUNTIF(Flips!$D$2:$D$135,A32) | C32: {=MEDIAN(IF(Flips!$D$2:$D$135=A32,Flips!$M$2:$M$135))} | D32: {=MEDIAN(IF(Flips!$D$2:$D$135=A32,Flips!$O$2:$O$135))}
A33: Italia | B33: =COUNTIF(Flips!$D$2:$D$135,A33) | C33: {=MEDIAN(IF(Flips!$D$2:$D$135=A33,Flips!$M$2:$M$135))} | D33: {=MEDIAN(IF(Flips!$D$2:$D$135=A33,Flips!$O$2:$O$135))}
A34: Hellas | B34: =COUNTIF(Flips!$D$2:$D$135,A34) | C34: {=MEDIAN(IF(Flips!$D$2:$D$135=A34,Flips!$M$2:$M$135))} | D34: {=MEDIAN(IF(Flips!$D$2:$D$135=A34,Flips!$O$2:$O$135))}
A35: USA | B35: =COUNTIF(Flips!$D$2:$D$135,A35) | C35: {=MEDIAN(IF(Flips!$D$2:$D$135=A35,Flips!$M$2:$M$135))} | D35: {=MEDIAN(IF(Flips!$D$2:$D$135=A35,Flips!$O$2:$O$135))}
A36: France | B36: =COUNTIF(Flips!$D$2:$D$135,A36) | C36: {=MEDIAN(IF(Flips!$D$2:$D$135=A36,Flips!$M$2:$M$135))} | D36: {=MEDIAN(IF(Flips!$D$2:$D$135=A36,Flips!$O$2:$O$135))}
A37: China | B37: =COUNTIF(Flips!$D$2:$D$135,A37) | C37: {=MEDIAN(IF(Flips!$D$2:$D$135=A37,Flips!$M$2:$M$135))} | D37: {=MEDIAN(IF(Flips!$D$2:$D$135=A37,Flips!$O$2:$O$135))}
A38: Deutschland | B38: =COUNTIF(Flips!$D$2:$D$135,A38) | C38: {=MEDIAN(IF(Flips!$D$2:$D$135=A38,Flips!$M$2:$M$135))} | D38: {=MEDIAN(IF(Flips!$D$2:$D$135=A38,Flips!$O$2:$O$135))}
A39: Pilipinas | B39: =COUNTIF(Flips!$D$2:$D$135,A39) | C39: {=MEDIAN(IF(Flips!$D$2:$D$135=A39,Flips!$M$2:$M$135))} | D39: {=MEDIAN(IF(Flips!$D$2:$D$135=A39,Flips!$O$2:$O$135))}
A40: Sverige | B40: =COUNTIF(Flips!$D$2:$D$135,A40) | C40: {=MEDIAN(IF(Flips!$D$2:$D$135=A40,Flips!$M$2:$M$135))} | D40: {=MEDIAN(IF(Flips!$D$2:$D$135=A40,Flips!$O$2:$O$135))}
... A69: Puerto Rico | B69: =COUNTIF(Flips!$D$2:$D$135,A69) | C69: {=MEDIAN(IF(Flips!$D$2:$D$135=A69,Flips!$M$2:$M$135))} | D69: {=MEDIAN(IF(Flips!$D$2:$D$135=A69,Flips!$O$2:$O$135))}
